Workbook

Sheet Cover
B2: DINO POLSKA S.A.
B3: Discounted Cash Flow Valuation Model
B4: Warsaw Stock Exchange (WSE: DNP) | PLN thousands | IFRS | April 2026
B6: About This Model
B7: Company: | C7: Dino Polska S.A.
B8: Sector: | C8: Food Retail / Supermarkets | HQ: Krotoszyn, Poland
B9: Exchange: | C9: Warsaw Stock Exchange (WSE) | Ticker: DNP
B10: Currency: | C10: PLN thousands unless stated
B11: Forecast: | C11: FY2026E – FY2032E (7-year explicit DCF period)
B12: Methodology: | C12: Unlevered FCF (FCFF) discounted at WACC; Gordon Growth terminal value
B13: Source Model: | C13: Dino_Polska_3-Statement_Model.xlsx
B16: Navigation
B17: ▶ WACC Build-Up | C17: Risk-free rate, ERP, beta, cost of debt → WACC
B18: ▶ DCF Valuation | C18: FCFF projection, terminal value, EV bridge → share price
B19: ▶ Sensitivity | C19: Share price sensitivity: WACC × Terminal Growth; EBIT margin × Revenue growth
B20: ▶ Comps | C20: EV/EBITDA, EV/EBIT, P/E trading comparables
B21: ▶ Football Field | C21: Valuation range summary across all methodologies
B24: Colour Coding
B25: ● Blue text | C25: Hard-coded inputs — change to run scenarios
B26: ● Black text | C26: Calculations / formulas
B27: ● Green text | C27: Links from the 3-Statement Model
B28: ● Red text | C28: Key outputs — implied share price

Sheet WACC Build-Up
B3: DINO POLSKA S.A. — WACC Build-Up
B4: PLN | April 2026 | CAPM-based cost of equity + after-tax cost of debt
B6: Component | D6: Value | E6: Notes / Source
B8: COST OF EQUITY (CAPM)
B9: Risk-Free Rate (Rf) | D9: 0.055 | E9: Polish 10Y government bond yield — NBP, April 2026
B10: Equity Risk Premium (ERP) | D10: 0.055 | E10: Damodaran ERP for Poland — 2025 update
B11: Beta (levered, 5Y monthly vs WIG) | D11: 0.85 | E11: Regression vs WIG; food retail is defensive
B12: Size / Country Risk Premium | D12: 0.005 | E12: Small premium for Polish mid-cap liquidity
B13: Cost of Equity (Ke) | D13: =D9+D11*D10+D12 -> 0.10675 | E13: Rf + beta x ERP + Size
B15: COST OF DEBT
B16: Pre-tax Cost of Debt (Kd) | D16: 0.055 | E16: Avg borrowing rate from 3-Statement Model (2025A)
B17: Tax Rate | D17: 0.19 | E17: Polish CIT rate — consistent with 3-Statement Model
B18: After-tax Cost of Debt (Kd × (1−t)) | D18: =D16*(1-D17) -> 0.04455
B20: CAPITAL STRUCTURE
B21: Market Capitalisation (PLN thousands) | D21: 14500000 | E21: DNP price × shares — April 2026 estimate
B22: Total Debt (PLN thousands) | D22: 987278 | E22: ST + LT bank debt + bonds — 2025A Balance Sheet
B23: Total Capital (E + D) | D23: =D21+D22 -> 15487278
B24: Equity Weight (E / (E+D)) | D24: =D21/D23 -> 0.93625232
B25: Debt Weight (D / (E+D)) | D25: =D22/D23 -> 0.063747677
B27: WACC | D27: =D13*D24+D18*D25 -> 0.10278489 | E27: ← pulled into DCF & Sensitivity sheets
B29: Note: Adjust blue cells to reflect updated market data. WACC feeds automatically into DCF Valuation and Sensitivity sheets.

Sheet DCF Valuation
B3: DINO POLSKA S.A. — DCF Valuation
B4: FCFF | 7-year explicit period 2026E–2032E | PLN thousands | Mid-year discounting
B6: PLN thousands | D6: 2026E | E6: 2027E | F6: 2028E | G6: 2029E | H6: 2030E | I6: 2031E | J6: 2032E | K6: Notes
B8: A. FREE CASH FLOW TO FIRM (FCFF)
B9: Revenue | D9: 39233204 | E9: 44763943 | F9: 50166222 | G9: =F9*(1+G10) -> 55182844 | H9: =G9*(1+H10) -> 60149300 | I9: =H9*(1+I10) -> 64961244 | J9: =I9*(1+J10) -> 69508531 | K9: 2026–28: from 3-Statement Model
B10: Revenue Growth % | D10: "-" | E10: =E9/D9-1 -> 0.14097087 | F10: =F9/E9-1 -> 0.12068372 | G10: 0.1 | H10: 0.09 | I10: 0.08 | J10: 0.07
B11: EBIT | D11: 2471692 | E11: 2909656 | F11: 3411303 | G11: =G9*G12 -> 3752433.4 | H11: =H9*H12 -> 4210451 | I11: =I9*I12 -> 4677209.6 | J11: =J9*J12 -> 5143631.3
B12: EBIT Margin % | D12: =D11/D9 -> 0.063000004 | E12: =E11/E9 -> 0.064999993 | F12: =F11/F9 -> 0.067999998 | G12: 0.068 | H12: 0.07 | I12: 0.072 | J12: 0.074
B13: NOPAT = EBIT × (1 − 19%) | D13: =D11*(1-0.19) -> 2002070.5 | E13: =E11*(1-0.19) -> 2356821.4 | F13: =F11*(1-0.19) -> 2763155.4 | G13: =G11*(1-0.19) -> 3039471.1 | H13: =H11*(1-0.19) -> 3410465.3 | I13: =I11*(1-0.19) -> 3788539.8 | J13: =J11*(1-0.19) -> 4166341.4
B14: (+) D&A | D14: 627731 | E14: 671459 | F14: 752493 | G14: =G9*G15 -> 827742.66 | H14: =H9*H15 -> 902239.5 | I14: =I9*I15 -> 909457.42 | J14: =J9*J15 -> 973119.44
B15: D&A % Revenue | D15: =D14/D9 -> 0.015999993 | E15: =E14/E9 -> 0.014999997 | F15: =F14/F9 -> 0.014999993 | G15: 0.015 | H15: 0.015 | I15: 0.014 | J15: 0.014
B16: (−) Capex | D16: -2353992 | E16: -2596309 | F16: -2759142 | G16: =G9*G17 -> -2924690.7 | H16: =H9*H17 -> -3067614.3 | I16: =I9*I17 -> -3183101 | J16: =J9*J17 -> -3266901
B17: Capex % Revenue | D17: =D16/D9 -> -0.059999994 | E17: =E16/E9 -> -0.058000007 | F17: =F16/F9 -> -0.054999996 | G17: -0.053 | H17: -0.051 | I17: -0.049 | J17: -0.047
B18: (−) Change in NWC | D18: -454814 | E18: 0 | F18: 0 | G18: =G9*G19 -> -551828.44 | H18: =H9*H19 -> -541343.7 | I18: =I9*I19 -> -519689.95 | J18: =J9*J19 -> -486559.72
B19: NWC Change % Revenue | D19: =IF(D9=0,0,D18/D9) -> -0.011592579 | E19: =IF(E9=0,0,E18/E9) -> 0 | F19: =IF(F9=0,0,F18/F9) -> 0 | G19: -0.01 | H19: -0.009 | I19: -0.008 | J19: -0.007
B20: Free Cash Flow to Firm (FCFF) | D20: =D13+D14+D16+D18 -> -179004.48 | E20: =E13+E14+E16+E18 -> 431971.36 | F20: =F13+F14+F16+F18 -> 756506.43 | G20: =G13+G14+G16+G18 -> 390694.54 | H20: =H13+H14+H16+H18 -> 703746.81 | I20: =I13+I14+I16+I18 -> 995206.26 | J20: =J13+J14+J16+J18 -> 1386000.1
B22: B. DISCOUNTING (Mid-Year Convention)
B23: WACC | D23: ='WACC Build-Up'!D27 -> 0.10278489 | E23: ← from WACC Build-Up
B24: Discount Period (mid-year) | D24: 0.5 | E24: 1.5 | F24: 2.5 | G24: 3.5 | H24: 4.5 | I24: 5.5 | J24: 6.5
B25: Discount Factor | D25: =1/(1+$D$23)^D24 -> 0.95225792 | E25: =1/(1+$D$23)^E24 -> 0.86350287 | F25: =1/(1+$D$23)^F24 -> 0.78302022 | G25: =1/(1+$D$23)^G24 -> 0.71003894 | H25: =1/(1+$D$23)^H24 -> 0.64385988 | I25: =1/(1+$D$23)^I24 -> 0.58384902 | J25: =1/(1+$D$23)^J24 -> 0.52943146
B26: PV of FCFF | D26: =D20*D25 -> -170458.43 | E26: =E20*E25 -> 373008.51 | F26: =F20*F25 -> 592359.83 | G26: =G20*G25 -> 277408.34 | H26: =H20*H25 -> 453114.33 | I26: =I20*I25 -> 581050.2 | J26: =J20*J25 -> 733792.06
B28: C. TERMINAL VALUE (Gordon Growth Model)
B29: Terminal Growth Rate (g) | D29: 0.03 | E29: Long-run nominal GDP growth for Poland
B30: Terminal FCFF (FCFF_2032 × (1+g)) | D30: =J20*(1+D29) -> 1427580.1
B31: Terminal Value = FCFF_t / (WACC − g) | D31: =D30/(D23-D29) -> 19613687
B32: PV of Terminal Value | D32: =D31/(1+D23)^7 -> 9888344.2
B34: TV as % of Total EV | D34: =D32/(SUM(D26:J26)+D32) -> 0.77685915
B36: D. VALUATION BRIDGE → SHARE PRICE
B37: Sum of PV(FCFFs) | D37: =SUM(D26:J26) -> 2840274.8
B38: (+) PV of Terminal Value | D38: =D32 -> 9888344.2
B39: Enterprise Value (EV) | D39: =D37+D38 -> 12728619
B40: (−) Net Debt (2025A) | D40: 32464 | E40: Debt 987,278 − Cash 954,814 = 32,464 | 2025A Balance Sheet
B41: (−) Minorities (2025A) | D41: 17720 | E41: Non-controlling interests — 2025A Balance Sheet
B42: Equity Value | D42: =D39-D40-D41 -> 12678435
B43: Shares Outstanding (thousands) | D43: 98040 | E43: 98,040 thousand shares — DNP 2025 Annual Report
B44: Implied Share Price (PLN) | D44: =D42/D43*1000 -> 129319 | E44: ← DCF INTRINSIC VALUE PER SHARE
B46: E. IMPLIED MULTIPLES (Sanity Check — 2025A)
B47: EV / EBITDA (2025A EBITDA = 2,546,313) | D47: =D39/2546313 -> 4.998843
B48: EV / EBIT (2025A EBIT = 2,041,282) | D48: =D39/2041282 -> 6.2356005
B49: P / E (2025A Net Profit = 1,558,797) | D49: =D42/1558797 -> 8.1334741

Sheet Sensitivity
B3: DINO POLSKA S.A. — Sensitivity Analysis
B4: Implied Share Price (PLN) | Two-variable data tables
B6: TABLE 1 — Implied Share Price vs. WACC × Terminal Growth Rate
B7: WACC ↓ / TGR → | D7: 0.02 | E7: 0.025 | F7: 0.03 | G7: 0.035 | H7: 0.04
B8: 0.07 | D8: =('DCF Valuation'!D20/(1+0.07)^0.5 + 'DCF Valuation'!E20/(1+0.07)^1.5 + 'DCF Valuation'!F20/(1+0.07)^2.5 + 'DCF Valuation'!G20/(1+0.07)^3.5 + 'DCF Valuation'!H20/(1+0.07)^4.5 + 'DCF Valuation'!I20/(1+0.07)^5.5 + 'DCF Valuation'!J20/(1+0.07)^6.5+'DCF Valuation'!J20*(1+0.02)/(0.07-0.02)/(1+0.07)^7-32464-17720)/98040*1000 -> 212360.71 | E8: =('DCF Valuation'!D20/(1+0.07)^0.5 + 'DCF Valuation'!E20/(1+0.07)^1.5 + 'DCF Valuation'!F20/(1+0.07)^2.5 + 'DCF Valuation'!G20/(1+0.07)^3.5 + 'DCF Valuation'!H20/(1+0.07)^4.5 + 'DCF Valuation'!I20/(1+0.07)^5.5 + 'DCF Valuation'!J20/(1+0.07)^6.5+'DCF Valuation'!J20*(1+0.025)/(0.07-0.025)/(1+0.07)^7-32464-17720)/98040*1000 -> 233294.36 | F8: =('DCF Valuation'!D20/(1+0.07)^0.5 + 'DCF Valuation'!E20/(1+0.07)^1.5 + 'DCF Valuation'!F20/(1+0.07)^2.5 + 'DCF Valuation'!G20/(1+0.07)^3.5 + 'DCF Valuation'!H20/(1+0.07)^4.5 + 'DCF Valuation'!I20/(1+0.07)^5.5 + 'DCF Valuation'!J20/(1+0.07)^6.5+'DCF Valuation'!J20*(1+0.03)/(0.07-0.03)/(1+0.07)^7-32464-17720)/98040*1000 -> 259461.41 | G8: =('DCF Valuation'!D20/(1+0.07)^0.5 + 'DCF Valuation'!E20/(1+0.07)^1.5 + 'DCF Valuation'!F20/(1+0.07)^2.5 + 'DCF Valuation'!G20/(1+0.07)^3.5 + 'DCF Valuation'!H20/(1+0.07)^4.5 + 'DCF Valuation'!I20/(1+0.07)^5.5 + 'DCF Valuation'!J20/(1+0.07)^6.5+'DCF Valuation'!J20*(1+0.035)/(0.07-0.035)/(1+0.07)^7-32464-17720)/98040*1000 -> 293104.76 | H8: =('DCF Valuation'!D20/(1+0.07)^0.5 + 'DCF Valuation'!E20/(1+0.07)^1.5 + 'DCF Valuation'!F20/(1+0.07)^2.5 + 'DCF Valuation'!G20/(1+0.07)^3.5 + 'DCF Valuation'!H20/(1+0.07)^4.5 + 'DCF Valuation'!I20/(1+0.07)^5.5 + 'DCF Valuation'!J20/(1+0.07)^6.5+'DCF Valuation'!J20*(1+0.04)/(0.07-0.04)/(1+0.07)^7-32464-17720)/98040*1000 -> 337962.56
B9: 0.075 | D9: =('DCF Valuation'!D20/(1+0.075)^0.5 + 'DCF Valuation'!E20/(1+0.075)^1.5 + 'DCF Valuation'!F20/(1+0.075)^2.5 + 'DCF Valuation'!G20/(1+0.075)^3.5 + 'DCF Valuation'!H20/(1+0.075)^4.5 + 'DCF Valuation'!I20/(1+0.075)^5.5 + 'DCF Valuation'!J20/(1+0.075)^6.5+'DCF Valuation'!J20*(1+0.02)/(0.075-0.02)/(1+0.075)^7-32464-17720)/98040*1000 -> 190082.44 | E9: =('DCF Valuation'!D20/(1+0.075)^0.5 + 'DCF Valuation'!E20/(1+0.075)^1.5 + 'DCF Valuation'!F20/(1+0.075)^2.5 + 'DCF Valuation'!G20/(1+0.075)^3.5 + 'DCF Valuation'!H20/(1+0.075)^4.5 + 'DCF Valuation'!I20/(1+0.075)^5.5 + 'DCF Valuation'!J20/(1+0.075)^6.5+'DCF Valuation'!J20*(1+0.025)/(0.075-0.025)/(1+0.075)^7-32464-17720)/98040*1000 -> 206737.51 | F9: =('DCF Valuation'!D20/(1+0.075)^0.5 + 'DCF Valuation'!E20/(1+0.075)^1.5 + 'DCF Valuation'!F20/(1+0.075)^2.5 + 'DCF Valuation'!G20/(1+0.075)^3.5 + 'DCF Valuation'!H20/(1+0.075)^4.5 + 'DCF Valuation'!I20/(1+0.075)^5.5 + 'DCF Valuation'!J20/(1+0.075)^6.5+'DCF Valuation'!J20*(1+0.03)/(0.075-0.03)/(1+0.075)^7-32464-17720)/98040*1000 -> 227093.71 | G9: =('DCF Valuation'!D20/(1+0.075)^0.5 + 'DCF Valuation'!E20/(1+0.075)^1.5 + 'DCF Valuation'!F20/(1+0.075)^2.5 + 'DCF Valuation'!G20/(1+0.075)^3.5 + 'DCF Valuation'!H20/(1+0.075)^4.5 + 'DCF Valuation'!I20/(1+0.075)^5.5 + 'DCF Valuation'!J20/(1+0.075)^6.5+'DCF Valuation'!J20*(1+0.035)/(0.075-0.035)/(1+0.075)^7-32464-17720)/98040*1000 -> 252538.95 | H9: =('DCF Valuation'!D20/(1+0.075)^0.5 + 'DCF Valuation'!E20/(1+0.075)^1.5 + 'DCF Valuation'!F20/(1+0.075)^2.5 + 'DCF Valuation'!G20/(1+0.075)^3.5 + 'DCF Valuation'!H20/(1+0.075)^4.5 + 'DCF Valuation'!I20/(1+0.075)^5.5 + 'DCF Valuation'!J20/(1+0.075)^6.5+'DCF Valuation'!J20*(1+0.04)/(0.075-0.04)/(1+0.075)^7-32464-17720)/98040*1000 -> 285254.27
B10: 0.08 | D10: =('DCF Valuation'!D20/(1+0.08)^0.5 + 'DCF Valuation'!E20/(1+0.08)^1.5 + 'DCF Valuation'!F20/(1+0.08)^2.5 + 'DCF Valuation'!G20/(1+0.08)^3.5 + 'DCF Valuation'!H20/(1+0.08)^4.5 + 'DCF Valuation'!I20/(1+0.08)^5.5 + 'DCF Valuation'!J20/(1+0.08)^6.5+'DCF Valuation'!J20*(1+0.02)/(0.08-0.02)/(1+0.08)^7-32464-17720)/98040*1000 -> 171594.52 | E10: =('DCF Valuation'!D20/(1+0.08)^0.5 + 'DCF Valuation'!E20/(1+0.08)^1.5 + 'DCF Valuation'!F20/(1+0.08)^2.5 + 'DCF Valuation'!G20/(1+0.08)^3.5 + 'DCF Valuation'!H20/(1+0.08)^4.5 + 'DCF Valuation'!I20/(1+0.08)^5.5 + 'DCF Valuation'!J20/(1+0.08)^6.5+'DCF Valuation'!J20*(1+0.025)/(0.08-0.025)/(1+0.08)^7-32464-17720)/98040*1000 -> 185092.64 | F10: =('DCF Valuation'!D20/(1+0.08)^0.5 + 'DCF Valuation'!E20/(1+0.08)^1.5 + 'DCF Valuation'!F20/(1+0.08)^2.5 + 'DCF Valuation'!G20/(1+0.08)^3.5 + 'DCF Valuation'!H20/(1+0.08)^4.5 + 'DCF Valuation'!I20/(1+0.08)^5.5 + 'DCF Valuation'!J20/(1+0.08)^6.5+'DCF Valuation'!J20*(1+0.03)/(0.08-0.03)/(1+0.08)^7-32464-17720)/98040*1000 -> 201290.39 | G10: =('DCF Valuation'!D20/(1+0.08)^0.5 + 'DCF Valuation'!E20/(1+0.08)^1.5 + 'DCF Valuation'!F20/(1+0.08)^2.5 + 'DCF Valuation'!G20/(1+0.08)^3.5 + 'DCF Valuation'!H20/(1+0.08)^4.5 + 'DCF Valuation'!I20/(1+0.08)^5.5 + 'DCF Valuation'!J20/(1+0.08)^6.5+'DCF Valuation'!J20*(1+0.035)/(0.08-0.035)/(1+0.08)^7-32464-17720)/98040*1000 -> 221087.65 | H10: =('DCF Valuation'!D20/(1+0.08)^0.5 + 'DCF Valuation'!E20/(1+0.08)^1.5 + 'DCF Valuation'!F20/(1+0.08)^2.5 + 'DCF Valuation'!G20/(1+0.08)^3.5 + 'DCF Valuation'!H20/(1+0.08)^4.5 + 'DCF Valuation'!I20/(1+0.08)^5.5 + 'DCF Valuation'!J20/(1+0.08)^6.5+'DCF Valuation'!J20*(1+0.04)/(0.08-0.04)/(1+0.08)^7-32464-17720)/98040*1000 -> 245834.21
B11: 0.085 | D11: =('DCF Valuation'!D20/(1+0.085)^0.5 + 'DCF Valuation'!E20/(1+0.085)^1.5 + 'DCF Valuation'!F20/(1+0.085)^2.5 + 'DCF Valuation'!G20/(1+0.085)^3.5 + 'DCF Valuation'!H20/(1+0.085)^4.5 + 'DCF Valuation'!I20/(1+0.085)^5.5 + 'DCF Valuation'!J20/(1+0.085)^6.5+'DCF Valuation'!J20*(1+0.02)/(0.085-0.02)/(1+0.085)^7-32464-17720)/98040*1000 -> 156019.55 | E11: =('DCF Valuation'!D20/(1+0.085)^0.5 + 'DCF Valuation'!E20/(1+0.085)^1.5 + 'DCF Valuation'!F20/(1+0.085)^2.5 + 'DCF Valuation'!G20/(1+0.085)^3.5 + 'DCF Valuation'!H20/(1+0.085)^4.5 + 'DCF Valuation'!I20/(1+0.085)^5.5 + 'DCF Valuation'!J20/(1+0.085)^6.5+'DCF Valuation'!J20*(1+0.025)/(0.085-0.025)/(1+0.085)^7-32464-17720)/98040*1000 -> 167128.85 | F11: =('DCF Valuation'!D20/(1+0.085)^0.5 + 'DCF Valuation'!E20/(1+0.085)^1.5 + 'DCF Valuation'!F20/(1+0.085)^2.5 + 'DCF Valuation'!G20/(1+0.085)^3.5 + 'DCF Valuation'!H20/(1+0.085)^4.5 + 'DCF Valuation'!I20/(1+0.085)^5.5 + 'DCF Valuation'!J20/(1+0.085)^6.5+'DCF Valuation'!J20*(1+0.03)/(0.085-0.03)/(1+0.085)^7-32464-17720)/98040*1000 -> 180258.03 | G11: =('DCF Valuation'!D20/(1+0.085)^0.5 + 'DCF Valuation'!E20/(1+0.085)^1.5 + 'DCF Valuation'!F20/(1+0.085)^2.5 + 'DCF Valuation'!G20/(1+0.085)^3.5 + 'DCF Valuation'!H20/(1+0.085)^4.5 + 'DCF Valuation'!I20/(1+0.085)^5.5 + 'DCF Valuation'!J20/(1+0.085)^6.5+'DCF Valuation'!J20*(1+0.035)/(0.085-0.035)/(1+0.085)^7-32464-17720)/98040*1000 -> 196013.05 | H11: =('DCF Valuation'!D20/(1+0.085)^0.5 + 'DCF Valuation'!E20/(1+0.085)^1.5 + 'DCF Valuation'!F20/(1+0.085)^2.5 + 'DCF Valuation'!G20/(1+0.085)^3.5 + 'DCF Valuation'!H20/(1+0.085)^4.5 + 'DCF Valuation'!I20/(1+0.085)^5.5 + 'DCF Valuation'!J20/(1+0.085)^6.5+'DCF Valuation'!J20*(1+0.04)/(0.085-0.04)/(1+0.085)^7-32464-17720)/98040*1000 -> 215269.18
B12: 0.09 | D12: =('DCF Valuation'!D20/(1+0.09)^0.5 + 'DCF Valuation'!E20/(1+0.09)^1.5 + 'DCF Valuation'!F20/(1+0.09)^2.5 + 'DCF Valuation'!G20/(1+0.09)^3.5 + 'DCF Valuation'!H20/(1+0.09)^4.5 + 'DCF Valuation'!I20/(1+0.09)^5.5 + 'DCF Valuation'!J20/(1+0.09)^6.5+'DCF Valuation'!J20*(1+0.02)/(0.09-0.02)/(1+0.09)^7-32464-17720)/98040*1000 -> 142730.92 | E12: =('DCF Valuation'!D20/(1+0.09)^0.5 + 'DCF Valuation'!E20/(1+0.09)^1.5 + 'DCF Valuation'!F20/(1+0.09)^2.5 + 'DCF Valuation'!G20/(1+0.09)^3.5 + 'DCF Valuation'!H20/(1+0.09)^4.5 + 'DCF Valuation'!I20/(1+0.09)^5.5 + 'DCF Valuation'!J20/(1+0.09)^6.5+'DCF Valuation'!J20*(1+0.025)/(0.09-0.025)/(1+0.09)^7-32464-17720)/98040*1000 -> 151994.09 | F12: =('DCF Valuation'!D20/(1+0.09)^0.5 + 'DCF Valuation'!E20/(1+0.09)^1.5 + 'DCF Valuation'!F20/(1+0.09)^2.5 + 'DCF Valuation'!G20/(1+0.09)^3.5 + 'DCF Valuation'!H20/(1+0.09)^4.5 + 'DCF Valuation'!I20/(1+0.09)^5.5 + 'DCF Valuation'!J20/(1+0.09)^6.5+'DCF Valuation'!J20*(1+0.03)/(0.09-0.03)/(1+0.09)^7-32464-17720)/98040*1000 -> 162801.12 | G12: =('DCF Valuation'!D20/(1+0.09)^0.5 + 'DCF Valuation'!E20/(1+0.09)^1.5 + 'DCF Valuation'!F20/(1+0.09)^2.5 + 'DCF Valuation'!G20/(1+0.09)^3.5 + 'DCF Valuation'!H20/(1+0.09)^4.5 + 'DCF Valuation'!I20/(1+0.09)^5.5 + 'DCF Valuation'!J20/(1+0.09)^6.5+'DCF Valuation'!J20*(1+0.035)/(0.09-0.035)/(1+0.09)^7-32464-17720)/98040*1000 -> 175573.07 | H12: =('DCF Valuation'!D20/(1+0.09)^0.5 + 'DCF Valuation'!E20/(1+0.09)^1.5 + 'DCF Valuation'!F20/(1+0.09)^2.5 + 'DCF Valuation'!G20/(1+0.09)^3.5 + 'DCF Valuation'!H20/(1+0.09)^4.5 + 'DCF Valuation'!I20/(1+0.09)^5.5 + 'DCF Valuation'!J20/(1+0.09)^6.5+'DCF Valuation'!J20*(1+0.04)/(0.09-0.04)/(1+0.09)^7-32464-17720)/98040*1000 -> 190899.4
B13: 0.095 | D13: =('DCF Valuation'!D20/(1+0.095)^0.5 + 'DCF Valuation'!E20/(1+0.095)^1.5 + 'DCF Valuation'!F20/(1+0.095)^2.5 + 'DCF Valuation'!G20/(1+0.095)^3.5 + 'DCF Valuation'!H20/(1+0.095)^4.5 + 'DCF Valuation'!I20/(1+0.095)^5.5 + 'DCF Valuation'!J20/(1+0.095)^6.5+'DCF Valuation'!J20*(1+0.02)/(0.095-0.02)/(1+0.095)^7-32464-17720)/98040*1000 -> 131269.23 | E13: =('DCF Valuation'!D20/(1+0.095)^0.5 + 'DCF Valuation'!E20/(1+0.095)^1.5 + 'DCF Valuation'!F20/(1+0.095)^2.5 + 'DCF Valuation'!G20/(1+0.095)^3.5 + 'DCF Valuation'!H20/(1+0.095)^4.5 + 'DCF Valuation'!I20/(1+0.095)^5.5 + 'DCF Valuation'!J20/(1+0.095)^6.5+'DCF Valuation'!J20*(1+0.025)/(0.095-0.025)/(1+0.095)^7-32464-17720)/98040*1000 -> 139079.86 | F13: =('DCF Valuation'!D20/(1+0.095)^0.5 + 'DCF Valuation'!E20/(1+0.095)^1.5 + 'DCF Valuation'!F20/(1+0.095)^2.5 + 'DCF Valuation'!G20/(1+0.095)^3.5 + 'DCF Valuation'!H20/(1+0.095)^4.5 + 'DCF Valuation'!I20/(1+0.095)^5.5 + 'DCF Valuation'!J20/(1+0.095)^6.5+'DCF Valuation'!J20*(1+0.03)/(0.095-0.03)/(1+0.095)^7-32464-17720)/98040*1000 -> 148092.12 | G13: =('DCF Valuation'!D20/(1+0.095)^0.5 + 'DCF Valuation'!E20/(1+0.095)^1.5 + 'DCF Valuation'!F20/(1+0.095)^2.5 + 'DCF Valuation'!G20/(1+0.095)^3.5 + 'DCF Valuation'!H20/(1+0.095)^4.5 + 'DCF Valuation'!I20/(1+0.095)^5.5 + 'DCF Valuation'!J20/(1+0.095)^6.5+'DCF Valuation'!J20*(1+0.035)/(0.095-0.035)/(1+0.095)^7-32464-17720)/98040*1000 -> 158606.43 | H13: =('DCF Valuation'!D20/(1+0.095)^0.5 + 'DCF Valuation'!E20/(1+0.095)^1.5 + 'DCF Valuation'!F20/(1+0.095)^2.5 + 'DCF Valuation'!G20/(1+0.095)^3.5 + 'DCF Valuation'!H20/(1+0.095)^4.5 + 'DCF Valuation'!I20/(1+0.095)^5.5 + 'DCF Valuation'!J20/(1+0.095)^6.5+'DCF Valuation'!J20*(1+0.04)/(0.095-0.04)/(1+0.095)^7-32464-17720)/98040*1000 -> 171032.43
B14: Base case highlighted (WACC=8.0%, TGR=3.0%)
B17: TABLE 2 — Implied Share Price vs. EBIT Margin × Revenue Growth (2029–32 avg)
B18: EBIT Margin ↓ / Rev Growth → | D18: 0.06 | E18: 0.07 | F18: 0.08 | G18: 0.09 | H18: 0.1
B19: 0.06 | D19: =('DCF Valuation'!D20/(1+0.08)^0.5 + 'DCF Valuation'!E20/(1+0.08)^1.5 + 'DCF Valuation'!F20/(1+0.08)^2.5+(((50166222*(1+0.06)^1)*0.06*(1-0.19)+(50166222*(1+0.06)^1)*0.015+(50166222*(1+0.06)^1)*-0.051+(50166222*(1+0.06)^1)*-0.009)/(1+0.08)^3.5) + (((50166222*(1+0.06)^2)*0.06*(1-0.19)+(50166222*(1+0.06)^2)*0.015+(50166222*(1+0.06)^2)*-0.051+(50166222*(1+0.06)^2)*-0.009)/(1+0.08)^4.5) + (((50166222*(1+0.06)^3)*0.06*(1-0.19)+(50166222*(1+0.06)^3)*0.015+(50166222*(1+0.06)^3)*-0.051+(50166222*(1+0.06)^3)*-0.009)/(1+0.08)^5.5) + (((50166222*(1+0.06)^4)*0.06*(1-0.19)+(50166222*(1+0.06)^4)*0.015+(50166222*(1+0.06)^4)*-0.051+(50166222*(1+0.06)^4)*-0.009)/(1+0.08)^6.5)+((50166222*(1+0.06)^4)*0.06*(1-0.19)+(50166222*(1+0.06)^4)*0.015+(50166222*(1+0.06)^4)*-0.051+(50166222*(1+0.06)^4)*-0.009)*(1+0.03)/(0.08-0.03)/(1+0.08)^7-32464-17720)/98040*1000 -> 41778.537 | E19: =('DCF Valuation'!D20/(1+0.08)^0.5 + 'DCF Valuation'!E20/(1+0.08)^1.5 + 'DCF Valuation'!F20/(1+0.08)^2.5+(((50166222*(1+0.07)^1)*0.06*(1-0.19)+(50166222*(1+0.07)^1)*0.015+(50166222*(1+0.07)^1)*-0.051+(50166222*(1+0.07)^1)*-0.009)/(1+0.08)^3.5) + (((50166222*(1+0.07)^2)*0.06*(1-0.19)+(50166222*(1+0.07)^2)*0.015+(50166222*(1+0.07)^2)*-0.051+(50166222*(1+0.07)^2)*-0.009)/(1+0.08)^4.5) + (((50166222*(1+0.07)^3)*0.06*(1-0.19)+(50166222*(1+0.07)^3)*0.015+(50166222*(1+0.07)^3)*-0.051+(50166222*(1+0.07)^3)*-0.009)/(1+0.08)^5.5) + (((50166222*(1+0.07)^4)*0.06*(1-0.19)+(50166222*(1+0.07)^4)*0.015+(50166222*(1+0.07)^4)*-0.051+(50166222*(1+0.07)^4)*-0.009)/(1+0.08)^6.5)+((50166222*(1+0.07)^4)*0.06*(1-0.19)+(50166222*(1+0.07)^4)*0.015+(50166222*(1+0.07)^4)*-0.051+(50166222*(1+0.07)^4)*-0.009)*(1+0.03)/(0.08-0.03)/(1+0.08)^7-32464-17720)/98040*1000 -> 42985.248 | F19: =('DCF Valuation'!D20/(1+0.08)^0.5 + 'DCF Valuation'!E20/(1+0.08)^1.5 + 'DCF Valuation'!F20/(1+0.08)^2.5+(((50166222*(1+0.08)^1)*0.06*(1-0.19)+(50166222*(1+0.08)^1)*0.015+(50166222*(1+0.08)^1)*-0.051+(50166222*(1+0.08)^1)*-0.009)/(1+0.08)^3.5) + (((50166222*(1+0.08)^2)*0.06*(1-0.19)+(50166222*(1+0.08)^2)*0.015+(50166222*(1+0.08)^2)*-0.051+(50166222*(1+0.08)^2)*-0.009)/(1+0.08)^4.5) + (((50166222*(1+0.08)^3)*0.06*(1-0.19)+(50166222*(1+0.08)^3)*0.015+(50166222*(1+0.08)^3)*-0.051+(50166222*(1+0.08)^3)*-0.009)/(1+0.08)^5.5) + (((50166222*(1+0.08)^4)*0.06*(1-0.19)+(50166222*(1+0.08)^4)*0.015+(50166222*(1+0.08)^4)*-0.051+(50166222*(1+0.08)^4)*-0.009)/(1+0.08)^6.5)+((50166222*(1+0.08)^4)*0.06*(1-0.19)+(50166222*(1+0.08)^4)*0.015+(50166222*(1+0.08)^4)*-0.051+(50166222*(1+0.08)^4)*-0.009)*(1+0.03)/(0.08-0.03)/(1+0.08)^7-32464-17720)/98040*1000 -> 44224.95 | G19: =('DCF Valuation'!D20/(1+0.08)^0.5 + 'DCF Valuation'!E20/(1+0.08)^1.5 + 'DCF Valuation'!F20/(1+0.08)^2.5+(((50166222*(1+0.09)^1)*0.06*(1-0.19)+(50166222*(1+0.09)^1)*0.015+(50166222*(1+0.09)^1)*-0.051+(50166222*(1+0.09)^1)*-0.009)/(1+0.08)^3.5) + (((50166222*(1+0.09)^2)*0.06*(1-0.19)+(50166222*(1+0.09)^2)*0.015+(50166222*(1+0.09)^2)*-0.051+(50166222*(1+0.09)^2)*-0.009)/(1+0.08)^4.5) + (((50166222*(1+0.09)^3)*0.06*(1-0.19)+(50166222*(1+0.09)^3)*0.015+(50166222*(1+0.09)^3)*-0.051+(50166222*(1+0.09)^3)*-0.009)/(1+0.08)^5.5) + (((50166222*(1+0.09)^4)*0.06*(1-0.19)+(50166222*(1+0.09)^4)*0.015+(50166222*(1+0.09)^4)*-0.051+(50166222*(1+0.09)^4)*-0.009)/(1+0.08)^6.5)+((50166222*(1+0.09)^4)*0.06*(1-0.19)+(50166222*(1+0.09)^4)*0.015+(50166222*(1+0.09)^4)*-0.051+(50166222*(1+0.09)^4)*-0.009)*(1+0.03)/(0.08-0.03)/(1+0.08)^7-32464-17720)/98040*1000 -> 45498.249 | H19: =('DCF Valuation'!D20/(1+0.08)^0.5 + 'DCF Valuation'!E20/(1+0.08)^1.5 + 'DCF Valuation'!F20/(1+0.08)^2.5+(((50166222*(1+0.1)^1)*0.06*(1-0.19)+(50166222*(1+0.1)^1)*0.015+(50166222*(1+0.1)^1)*-0.051+(50166222*(1+0.1)^1)*-0.009)/(1+0.08)^3.5) + (((50166222*(1+0.1)^2)*0.06*(1-0.19)+(50166222*(1+0.1)^2)*0.015+(50166222*(1+0.1)^2)*-0.051+(50166222*(1+0.1)^2)*-0.009)/(1+0.08)^4.5) + (((50166222*(1+0.1)^3)*0.06*(1-0.19)+(50166222*(1+0.1)^3)*0.015+(50166222*(1+0.1)^3)*-0.051+(50166222*(1+0.1)^3)*-0.009)/(1+0.08)^5.5) + (((50166222*(1+0.1)^4)*0.06*(1-0.19)+(50166222*(1+0.1)^4)*0.015+(50166222*(1+0.1)^4)*-0.051+(50166222*(1+0.1)^4)*-0.009)/(1+0.08)^6.5)+((50166222*(1+0.1)^4)*0.06*(1-0.19)+(50166222*(1+0.1)^4)*0.015+(50166222*(1+0.1)^4)*-0.051+(50166222*(1+0.1)^4)*-0.009)*(1+0.03)/(0.08-0.03)/(1+0.08)^7-32464-17720)/98040*1000 -> 46805.759
B20: 0.064 | D20: =('DCF Valuation'!D20/(1+0.08)^0.5 + 'DCF Valuation'!E20/(1+0.08)^1.5 + 'DCF Valuation'!F20/(1+0.08)^2.5+(((50166222*(1+0.06)^1)*0.064*(1-0.19)+(50166222*(1+0.06)^1)*0.015+(50166222*(1+0.06)^1)*-0.051+(50166222*(1+0.06)^1)*-0.009)/(1+0.08)^3.5) + (((50166222*(1+0.06)^2)*0.064*(1-0.19)+(50166222*(1+0.06)^2)*0.015+(50166222*(1+0.06)^2)*-0.051+(50166222*(1+0.06)^2)*-0.009)/(1+0.08)^4.5) + (((50166222*(1+0.06)^3)*0.064*(1-0.19)+(50166222*(1+0.06)^3)*0.015+(50166222*(1+0.06)^3)*-0.051+(50166222*(1+0.06)^3)*-0.009)/(1+0.08)^5.5) + (((50166222*(1+0.06)^4)*0.064*(1-0.19)+(50166222*(1+0.06)^4)*0.015+(50166222*(1+0.06)^4)*-0.051+(50166222*(1+0.06)^4)*-0.009)/(1+0.08)^6.5)+((50166222*(1+0.06)^4)*0.064*(1-0.19)+(50166222*(1+0.06)^4)*0.015+(50166222*(1+0.06)^4)*-0.051+(50166222*(1+0.06)^4)*-0.009)*(1+0.03)/(0.08-0.03)/(1+0.08)^7-32464-17720)/98040*1000 -> 72158.821 | E20: =('DCF Valuation'!D20/(1+0.08)^0.5 + 'DCF Valuation'!E20/(1+0.08)^1.5 + 'DCF Valuation'!F20/(1+0.08)^2.5+(((50166222*(1+0.07)^1)*0.064*(1-0.19)+(50166222*(1+0.07)^1)*0.015+(50166222*(1+0.07)^1)*-0.051+(50166222*(1+0.07)^1)*-0.009)/(1+0.08)^3.5) + (((50166222*(1+0.07)^2)*0.064*(1-0.19)+(50166222*(1+0.07)^2)*0.015+(50166222*(1+0.07)^2)*-0.051+(50166222*(1+0.07)^2)*-0.009)/(1+0.08)^4.5) + (((50166222*(1+0.07)^3)*0.064*(1-0.19)+(50166222*(1+0.07)^3)*0.015+(50166222*(1+0.07)^3)*-0.051+(50166222*(1+0.07)^3)*-0.009)/(1+0.08)^5.5) + (((50166222*(1+0.07)^4)*0.064*(1-0.19)+(50166222*(1+0.07)^4)*0.015+(50166222*(1+0.07)^4)*-0.051+(50166222*(1+0.07)^4)*-0.009)/(1+0.08)^6.5)+((50166222*(1+0.07)^4)*0.064*(1-0.19)+(50166222*(1+0.07)^4)*0.015+(50166222*(1+0.07)^4)*-0.051+(50166222*(1+0.07)^4)*-0.009)*(1+0.03)/(0.08-0.03)/(1+0.08)^7-32464-17720)/98040*1000 -> 74451.573 | F20: =('DCF Valuation'!D20/(1+0.08)^0.5 + 'DCF Valuation'!E20/(1+0.08)^1.5 + 'DCF Valuation'!F20/(1+0.08)^2.5+(((50166222*(1+0.08)^1)*0.064*(1-0.19)+(50166222*(1+0.08)^1)*0.015+(50166222*(1+0.08)^1)*-0.051+(50166222*(1+0.08)^1)*-0.009)/(1+0.08)^3.5) + (((50166222*(1+0.08)^2)*0.064*(1-0.19)+(50166222*(1+0.08)^2)*0.015+(50166222*(1+0.08)^2)*-0.051+(50166222*(1+0.08)^2)*-0.009)/(1+0.08)^4.5) + (((50166222*(1+0.08)^3)*0.064*(1-0.19)+(50166222*(1+0.08)^3)*0.015+(50166222*(1+0.08)^3)*-0.051+(50166222*(1+0.08)^3)*-0.009)/(1+0.08)^5.5) + (((50166222*(1+0.08)^4)*0.064*(1-0.19)+(50166222*(1+0.08)^4)*0.015+(50166222*(1+0.08)^4)*-0.051+(50166222*(1+0.08)^4)*-0.009)/(1+0.08)^6.5)+((50166222*(1+0.08)^4)*0.064*(1-0.19)+(50166222*(1+0.08)^4)*0.015+(50166222*(1+0.08)^4)*-0.051+(50166222*(1+0.08)^4)*-0.009)*(1+0.03)/(0.08-0.03)/(1+0.08)^7-32464-17720)/98040*1000 -> 76807.006 | G20: =('DCF Valuation'!D20/(1+0.08)^0.5 + 'DCF Valuation'!E20/(1+0.08)^1.5 + 'DCF Valuation'!F20/(1+0.08)^2.5+(((50166222*(1+0.09)^1)*0.064*(1-0.19)+(50166222*(1+0.09)^1)*0.015+(50166222*(1+0.09)^1)*-0.051+(50166222*(1+0.09)^1)*-0.009)/(1+0.08)^3.5) + (((50166222*(1+0.09)^2)*0.064*(1-0.19)+(50166222*(1+0.09)^2)*0.015+(50166222*(1+0.09)^2)*-0.051+(50166222*(1+0.09)^2)*-0.009)/(1+0.08)^4.5) + (((50166222*(1+0.09)^3)*0.064*(1-0.19)+(50166222*(1+0.09)^3)*0.015+(50166222*(1+0.09)^3)*-0.051+(50166222*(1+0.09)^3)*-0.009)/(1+0.08)^5.5) + (((50166222*(1+0.09)^4)*0.064*(1-0.19)+(50166222*(1+0.09)^4)*0.015+(50166222*(1+0.09)^4)*-0.051+(50166222*(1+0.09)^4)*-0.009)/(1+0.08)^6.5)+((50166222*(1+0.09)^4)*0.064*(1-0.19)+(50166222*(1+0.09)^4)*0.015+(50166222*(1+0.09)^4)*-0.051+(50166222*(1+0.09)^4)*-0.009)*(1+0.03)/(0.08-0.03)/(1+0.08)^7-32464-17720)/98040*1000 -> 79226.275 | H20: =('DCF Valuation'!D20/(1+0.08)^0.5 + 'DCF Valuation'!E20/(1+0.08)^1.5 + 'DCF Valuation'!F20/(1+0.08)^2.5+(((50166222*(1+0.1)^1)*0.064*(1-0.19)+(50166222*(1+0.1)^1)*0.015+(50166222*(1+0.1)^1)*-0.051+(50166222*(1+0.1)^1)*-0.009)/(1+0.08)^3.5) + (((50166222*(1+0.1)^2)*0.064*(1-0.19)+(50166222*(1+0.1)^2)*0.015+(50166222*(1+0.1)^2)*-0.051+(50166222*(1+0.1)^2)*-0.009)/(1+0.08)^4.5) + (((50166222*(1+0.1)^3)*0.064*(1-0.19)+(50166222*(1+0.1)^3)*0.015+(50166222*(1+0.1)^3)*-0.051+(50166222*(1+0.1)^3)*-0.009)/(1+0.08)^5.5) + (((50166222*(1+0.1)^4)*0.064*(1-0.19)+(50166222*(1+0.1)^4)*0.015+(50166222*(1+0.1)^4)*-0.051+(50166222*(1+0.1)^4)*-0.009)/(1+0.08)^6.5)+((50166222*(1+0.1)^4)*0.064*(1-0.19)+(50166222*(1+0.1)^4)*0.015+(50166222*(1+0.1)^4)*-0.051+(50166222*(1+0.1)^4)*-0.009)*(1+0.03)/(0.08-0.03)/(1+0.08)^7-32464-17720)/98040*1000 -> 81710.543
B21: 0.068 | D21: =('DCF Valuation'!D20/(1+0.08)^0.5 + 'DCF Valuation'!E20/(1+0.08)^1.5 + 'DCF Valuation'!F20/(1+0.08)^2.5+(((50166222*(1+0.06)^1)*0.068*(1-0.19)+(50166222*(1+0.06)^1)*0.015+(50166222*(1+0.06)^1)*-0.051+(50166222*(1+0.06)^1)*-0.009)/(1+0.08)^3.5) + (((50166222*(1+0.06)^2)*0.068*(1-0.19)+(50166222*(1+0.06)^2)*0.015+(50166222*(1+0.06)^2)*-0.051+(50166222*(1+0.06)^2)*-0.009)/(1+0.08)^4.5) + (((50166222*(1+0.06)^3)*0.068*(1-0.19)+(50166222*(1+0.06)^3)*0.015+(50166222*(1+0.06)^3)*-0.051+(50166222*(1+0.06)^3)*-0.009)/(1+0.08)^5.5) + (((50166222*(1+0.06)^4)*0.068*(1-0.19)+(50166222*(1+0.06)^4)*0.015+(50166222*(1+0.06)^4)*-0.051+(50166222*(1+0.06)^4)*-0.009)/(1+0.08)^6.5)+((50166222*(1+0.06)^4)*0.068*(1-0.19)+(50166222*(1+0.06)^4)*0.015+(50166222*(1+0.06)^4)*-0.051+(50166222*(1+0.06)^4)*-0.009)*(1+0.03)/(0.08-0.03)/(1+0.08)^7-32464-17720)/98040*1000 -> 102539.1 | E21: =('DCF Valuation'!D20/(1+0.08)^0.5 + 'DCF Valuation'!E20/(1+0.08)^1.5 + 'DCF Valuation'!F20/(1+0.08)^2.5+(((50166222*(1+0.07)^1)*0.068*(1-0.19)+(50166222*(1+0.07)^1)*0.015+(50166222*(1+0.07)^1)*-0.051+(50166222*(1+0.07)^1)*-0.009)/(1+0.08)^3.5) + (((50166222*(1+0.07)^2)*0.068*(1-0.19)+(50166222*(1+0.07)^2)*0.015+(50166222*(1+0.07)^2)*-0.051+(50166222*(1+0.07)^2)*-0.009)/(1+0.08)^4.5) + (((50166222*(1+0.07)^3)*0.068*(1-0.19)+(50166222*(1+0.07)^3)*0.015+(50166222*(1+0.07)^3)*-0.051+(50166222*(1+0.07)^3)*-0.009)/(1+0.08)^5.5) + (((50166222*(1+0.07)^4)*0.068*(1-0.19)+(50166222*(1+0.07)^4)*0.015+(50166222*(1+0.07)^4)*-0.051+(50166222*(1+0.07)^4)*-0.009)/(1+0.08)^6.5)+((50166222*(1+0.07)^4)*0.068*(1-0.19)+(50166222*(1+0.07)^4)*0.015+(50166222*(1+0.07)^4)*-0.051+(50166222*(1+0.07)^4)*-0.009)*(1+0.03)/(0.08-0.03)/(1+0.08)^7-32464-17720)/98040*1000 -> 105917.9 | F21: =('DCF Valuation'!D20/(1+0.08)^0.5 + 'DCF Valuation'!E20/(1+0.08)^1.5 + 'DCF Valuation'!F20/(1+0.08)^2.5+(((50166222*(1+0.08)^1)*0.068*(1-0.19)+(50166222*(1+0.08)^1)*0.015+(50166222*(1+0.08)^1)*-0.051+(50166222*(1+0.08)^1)*-0.009)/(1+0.08)^3.5) + (((50166222*(1+0.08)^2)*0.068*(1-0.19)+(50166222*(1+0.08)^2)*0.015+(50166222*(1+0.08)^2)*-0.051+(50166222*(1+0.08)^2)*-0.009)/(1+0.08)^4.5) + (((50166222*(1+0.08)^3)*0.068*(1-0.19)+(50166222*(1+0.08)^3)*0.015+(50166222*(1+0.08)^3)*-0.051+(50166222*(1+0.08)^3)*-0.009)/(1+0.08)^5.5) + (((50166222*(1+0.08)^4)*0.068*(1-0.19)+(50166222*(1+0.08)^4)*0.015+(50166222*(1+0.08)^4)*-0.051+(50166222*(1+0.08)^4)*-0.009)/(1+0.08)^6.5)+((50166222*(1+0.08)^4)*0.068*(1-0.19)+(50166222*(1+0.08)^4)*0.015+(50166222*(1+0.08)^4)*-0.051+(50166222*(1+0.08)^4)*-0.009)*(1+0.03)/(0.08-0.03)/(1+0.08)^7-32464-17720)/98040*1000 -> 109389.06 | G21: =('DCF Valuation'!D20/(1+0.08)^0.5 + 'DCF Valuation'!E20/(1+0.08)^1.5 + 'DCF Valuation'!F20/(1+0.08)^2.5+(((50166222*(1+0.09)^1)*0.068*(1-0.19)+(50166222*(1+0.09)^1)*0.015+(50166222*(1+0.09)^1)*-0.051+(50166222*(1+0.09)^1)*-0.009)/(1+0.08)^3.5) + (((50166222*(1+0.09)^2)*0.068*(1-0.19)+(50166222*(1+0.09)^2)*0.015+(50166222*(1+0.09)^2)*-0.051+(50166222*(1+0.09)^2)*-0.009)/(1+0.08)^4.5) + (((50166222*(1+0.09)^3)*0.068*(1-0.19)+(50166222*(1+0.09)^3)*0.015+(50166222*(1+0.09)^3)*-0.051+(50166222*(1+0.09)^3)*-0.009)/(1+0.08)^5.5) + (((50166222*(1+0.09)^4)*0.068*(1-0.19)+(50166222*(1+0.09)^4)*0.015+(50166222*(1+0.09)^4)*-0.051+(50166222*(1+0.09)^4)*-0.009)/(1+0.08)^6.5)+((50166222*(1+0.09)^4)*0.068*(1-0.19)+(50166222*(1+0.09)^4)*0.015+(50166222*(1+0.09)^4)*-0.051+(50166222*(1+0.09)^4)*-0.009)*(1+0.03)/(0.08-0.03)/(1+0.08)^7-32464-17720)/98040*1000 -> 112954.3 | H21: =('DCF Valuation'!D20/(1+0.08)^0.5 + 'DCF Valuation'!E20/(1+0.08)^1.5 + 'DCF Valuation'!F20/(1+0.08)^2.5+(((50166222*(1+0.1)^1)*0.068*(1-0.19)+(50166222*(1+0.1)^1)*0.015+(50166222*(1+0.1)^1)*-0.051+(50166222*(1+0.1)^1)*-0.009)/(1+0.08)^3.5) + (((50166222*(1+0.1)^2)*0.068*(1-0.19)+(50166222*(1+0.1)^2)*0.015+(50166222*(1+0.1)^2)*-0.051+(50166222*(1+0.1)^2)*-0.009)/(1+0.08)^4.5) + (((50166222*(1+0.1)^3)*0.068*(1-0.19)+(50166222*(1+0.1)^3)*0.015+(50166222*(1+0.1)^3)*-0.051+(50166222*(1+0.1)^3)*-0.009)/(1+0.08)^5.5) + (((50166222*(1+0.1)^4)*0.068*(1-0.19)+(50166222*(1+0.1)^4)*0.015+(50166222*(1+0.1)^4)*-0.051+(50166222*(1+0.1)^4)*-0.009)/(1+0.08)^6.5)+((50166222*(1+0.1)^4)*0.068*(1-0.19)+(50166222*(1+0.1)^4)*0.015+(50166222*(1+0.1)^4)*-0.051+(50166222*(1+0.1)^4)*-0.009)*(1+0.03)/(0.08-0.03)/(1+0.08)^7-32464-17720)/98040*1000 -> 116615.33
B22: 0.072 | D22: =('DCF Valuation'!D20/(1+0.08)^0.5 + 'DCF Valuation'!E20/(1+0.08)^1.5 + 'DCF Valuation'!F20/(1+0.08)^2.5+(((50166222*(1+0.06)^1)*0.072*(1-0.19)+(50166222*(1+0.06)^1)*0.015+(50166222*(1+0.06)^1)*-0.051+(50166222*(1+0.06)^1)*-0.009)/(1+0.08)^3.5) + (((50166222*(1+0.06)^2)*0.072*(1-0.19)+(50166222*(1+0.06)^2)*0.015+(50166222*(1+0.06)^2)*-0.051+(50166222*(1+0.06)^2)*-0.009)/(1+0.08)^4.5) + (((50166222*(1+0.06)^3)*0.072*(1-0.19)+(50166222*(1+0.06)^3)*0.015+(50166222*(1+0.06)^3)*-0.051+(50166222*(1+0.06)^3)*-0.009)/(1+0.08)^5.5) + (((50166222*(1+0.06)^4)*0.072*(1-0.19)+(50166222*(1+0.06)^4)*0.015+(50166222*(1+0.06)^4)*-0.051+(50166222*(1+0.06)^4)*-0.009)/(1+0.08)^6.5)+((50166222*(1+0.06)^4)*0.072*(1-0.19)+(50166222*(1+0.06)^4)*0.015+(50166222*(1+0.06)^4)*-0.051+(50166222*(1+0.06)^4)*-0.009)*(1+0.03)/(0.08-0.03)/(1+0.08)^7-32464-17720)/98040*1000 -> 132919.39 | E22: =('DCF Valuation'!D20/(1+0.08)^0.5 + 'DCF Valuation'!E20/(1+0.08)^1.5 + 'DCF Valuation'!F20/(1+0.08)^2.5+(((50166222*(1+0.07)^1)*0.072*(1-0.19)+(50166222*(1+0.07)^1)*0.015+(50166222*(1+0.07)^1)*-0.051+(50166222*(1+0.07)^1)*-0.009)/(1+0.08)^3.5) + (((50166222*(1+0.07)^2)*0.072*(1-0.19)+(50166222*(1+0.07)^2)*0.015+(50166222*(1+0.07)^2)*-0.051+(50166222*(1+0.07)^2)*-0.009)/(1+0.08)^4.5) + (((50166222*(1+0.07)^3)*0.072*(1-0.19)+(50166222*(1+0.07)^3)*0.015+(50166222*(1+0.07)^3)*-0.051+(50166222*(1+0.07)^3)*-0.009)/(1+0.08)^5.5) + (((50166222*(1+0.07)^4)*0.072*(1-0.19)+(50166222*(1+0.07)^4)*0.015+(50166222*(1+0.07)^4)*-0.051+(50166222*(1+0.07)^4)*-0.009)/(1+0.08)^6.5)+((50166222*(1+0.07)^4)*0.072*(1-0.19)+(50166222*(1+0.07)^4)*0.015+(50166222*(1+0.07)^4)*-0.051+(50166222*(1+0.07)^4)*-0.009)*(1+0.03)/(0.08-0.03)/(1+0.08)^7-32464-17720)/98040*1000 -> 137384.22 | F22: =('DCF Valuation'!D20/(1+0.08)^0.5 + 'DCF Valuation'!E20/(1+0.08)^1.5 + 'DCF Valuation'!F20/(1+0.08)^2.5+(((50166222*(1+0.08)^1)*0.072*(1-0.19)+(50166222*(1+0.08)^1)*0.015+(50166222*(1+0.08)^1)*-0.051+(50166222*(1+0.08)^1)*-0.009)/(1+0.08)^3.5) + (((50166222*(1+0.08)^2)*0.072*(1-0.19)+(50166222*(1+0.08)^2)*0.015+(50166222*(1+0.08)^2)*-0.051+(50166222*(1+0.08)^2)*-0.009)/(1+0.08)^4.5) + (((50166222*(1+0.08)^3)*0.072*(1-0.19)+(50166222*(1+0.08)^3)*0.015+(50166222*(1+0.08)^3)*-0.051+(50166222*(1+0.08)^3)*-0.009)/(1+0.08)^5.5) + (((50166222*(1+0.08)^4)*0.072*(1-0.19)+(50166222*(1+0.08)^4)*0.015+(50166222*(1+0.08)^4)*-0.051+(50166222*(1+0.08)^4)*-0.009)/(1+0.08)^6.5)+((50166222*(1+0.08)^4)*0.072*(1-0.19)+(50166222*(1+0.08)^4)*0.015+(50166222*(1+0.08)^4)*-0.051+(50166222*(1+0.08)^4)*-0.009)*(1+0.03)/(0.08-0.03)/(1+0.08)^7-32464-17720)/98040*1000 -> 141971.12 | G22: =('DCF Valuation'!D20/(1+0.08)^0.5 + 'DCF Valuation'!E20/(1+0.08)^1.5 + 'DCF Valuation'!F20/(1+0.08)^2.5+(((50166222*(1+0.09)^1)*0.072*(1-0.19)+(50166222*(1+0.09)^1)*0.015+(50166222*(1+0.09)^1)*-0.051+(50166222*(1+0.09)^1)*-0.009)/(1+0.08)^3.5) + (((50166222*(1+0.09)^2)*0.072*(1-0.19)+(50166222*(1+0.09)^2)*0.015+(50166222*(1+0.09)^2)*-0.051+(50166222*(1+0.09)^2)*-0.009)/(1+0.08)^4.5) + (((50166222*(1+0.09)^3)*0.072*(1-0.19)+(50166222*(1+0.09)^3)*0.015+(50166222*(1+0.09)^3)*-0.051+(50166222*(1+0.09)^3)*-0.009)/(1+0.08)^5.5) + (((50166222*(1+0.09)^4)*0.072*(1-0.19)+(50166222*(1+0.09)^4)*0.015+(50166222*(1+0.09)^4)*-0.051+(50166222*(1+0.09)^4)*-0.009)/(1+0.08)^6.5)+((50166222*(1+0.09)^4)*0.072*(1-0.19)+(50166222*(1+0.09)^4)*0.015+(50166222*(1+0.09)^4)*-0.051+(50166222*(1+0.09)^4)*-0.009)*(1+0.03)/(0.08-0.03)/(1+0.08)^7-32464-17720)/98040*1000 -> 146682.33 | H22: =('DCF Valuation'!D20/(1+0.08)^0.5 + 'DCF Valuation'!E20/(1+0.08)^1.5 + 'DCF Valuation'!F20/(1+0.08)^2.5+(((50166222*(1+0.1)^1)*0.072*(1-0.19)+(50166222*(1+0.1)^1)*0.015+(50166222*(1+0.1)^1)*-0.051+(50166222*(1+0.1)^1)*-0.009)/(1+0.08)^3.5) + (((50166222*(1+0.1)^2)*0.072*(1-0.19)+(50166222*(1+0.1)^2)*0.015+(50166222*(1+0.1)^2)*-0.051+(50166222*(1+0.1)^2)*-0.009)/(1+0.08)^4.5) + (((50166222*(1+0.1)^3)*0.072*(1-0.19)+(50166222*(1+0.1)^3)*0.015+(50166222*(1+0.1)^3)*-0.051+(50166222*(1+0.1)^3)*-0.009)/(1+0.08)^5.5) + (((50166222*(1+0.1)^4)*0.072*(1-0.19)+(50166222*(1+0.1)^4)*0.015+(50166222*(1+0.1)^4)*-0.051+(50166222*(1+0.1)^4)*-0.009)/(1+0.08)^6.5)+((50166222*(1+0.1)^4)*0.072*(1-0.19)+(50166222*(1+0.1)^4)*0.015+(50166222*(1+0.1)^4)*-0.051+(50166222*(1+0.1)^4)*-0.009)*(1+0.03)/(0.08-0.03)/(1+0.08)^7-32464-17720)/98040*1000 -> 151520.11
B23: 0.076 | D23: =('DCF Valuation'!D20/(1+0.08)^0.5 + 'DCF Valuation'!E20/(1+0.08)^1.5 + 'DCF Valuation'!F20/(1+0.08)^2.5+(((50166222*(1+0.06)^1)*0.076*(1-0.19)+(50166222*(1+0.06)^1)*0.015+(50166222*(1+0.06)^1)*-0.051+(50166222*(1+0.06)^1)*-0.009)/(1+0.08)^3.5) + (((50166222*(1+0.06)^2)*0.076*(1-0.19)+(50166222*(1+0.06)^2)*0.015+(50166222*(1+0.06)^2)*-0.051+(50166222*(1+0.06)^2)*-0.009)/(1+0.08)^4.5) + (((50166222*(1+0.06)^3)*0.076*(1-0.19)+(50166222*(1+0.06)^3)*0.015+(50166222*(1+0.06)^3)*-0.051+(50166222*(1+0.06)^3)*-0.009)/(1+0.08)^5.5) + (((50166222*(1+0.06)^4)*0.076*(1-0.19)+(50166222*(1+0.06)^4)*0.015+(50166222*(1+0.06)^4)*-0.051+(50166222*(1+0.06)^4)*-0.009)/(1+0.08)^6.5)+((50166222*(1+0.06)^4)*0.076*(1-0.19)+(50166222*(1+0.06)^4)*0.015+(50166222*(1+0.06)^4)*-0.051+(50166222*(1+0.06)^4)*-0.009)*(1+0.03)/(0.08-0.03)/(1+0.08)^7-32464-17720)/98040*1000 -> 163299.67 | E23: =('DCF Valuation'!D20/(1+0.08)^0.5 + 'DCF Valuation'!E20/(1+0.08)^1.5 + 'DCF Valuation'!F20/(1+0.08)^2.5+(((50166222*(1+0.07)^1)*0.076*(1-0.19)+(50166222*(1+0.07)^1)*0.015+(50166222*(1+0.07)^1)*-0.051+(50166222*(1+0.07)^1)*-0.009)/(1+0.08)^3.5) + (((50166222*(1+0.07)^2)*0.076*(1-0.19)+(50166222*(1+0.07)^2)*0.015+(50166222*(1+0.07)^2)*-0.051+(50166222*(1+0.07)^2)*-0.009)/(1+0.08)^4.5) + (((50166222*(1+0.07)^3)*0.076*(1-0.19)+(50166222*(1+0.07)^3)*0.015+(50166222*(1+0.07)^3)*-0.051+(50166222*(1+0.07)^3)*-0.009)/(1+0.08)^5.5) + (((50166222*(1+0.07)^4)*0.076*(1-0.19)+(50166222*(1+0.07)^4)*0.015+(50166222*(1+0.07)^4)*-0.051+(50166222*(1+0.07)^4)*-0.009)/(1+0.08)^6.5)+((50166222*(1+0.07)^4)*0.076*(1-0.19)+(50166222*(1+0.07)^4)*0.015+(50166222*(1+0.07)^4)*-0.051+(50166222*(1+0.07)^4)*-0.009)*(1+0.03)/(0.08-0.03)/(1+0.08)^7-32464-17720)/98040*1000 -> 168850.55 | F23: =('DCF Valuation'!D20/(1+0.08)^0.5 + 'DCF Valuation'!E20/(1+0.08)^1.5 + 'DCF Valuation'!F20/(1+0.08)^2.5+(((50166222*(1+0.08)^1)*0.076*(1-0.19)+(50166222*(1+0.08)^1)*0.015+(50166222*(1+0.08)^1)*-0.051+(50166222*(1+0.08)^1)*-0.009)/(1+0.08)^3.5) + (((50166222*(1+0.08)^2)*0.076*(1-0.19)+(50166222*(1+0.08)^2)*0.015+(50166222*(1+0.08)^2)*-0.051+(50166222*(1+0.08)^2)*-0.009)/(1+0.08)^4.5) + (((50166222*(1+0.08)^3)*0.076*(1-0.19)+(50166222*(1+0.08)^3)*0.015+(50166222*(1+0.08)^3)*-0.051+(50166222*(1+0.08)^3)*-0.009)/(1+0.08)^5.5) + (((50166222*(1+0.08)^4)*0.076*(1-0.19)+(50166222*(1+0.08)^4)*0.015+(50166222*(1+0.08)^4)*-0.051+(50166222*(1+0.08)^4)*-0.009)/(1+0.08)^6.5)+((50166222*(1+0.08)^4)*0.076*(1-0.19)+(50166222*(1+0.08)^4)*0.015+(50166222*(1+0.08)^4)*-0.051+(50166222*(1+0.08)^4)*-0.009)*(1+0.03)/(0.08-0.03)/(1+0.08)^7-32464-17720)/98040*1000 -> 174553.17 | G23: =('DCF Valuation'!D20/(1+0.08)^0.5 + 'DCF Valuation'!E20/(1+0.08)^1.5 + 'DCF Valuation'!F20/(1+0.08)^2.5+(((50166222*(1+0.09)^1)*0.076*(1-0.19)+(50166222*(1+0.09)^1)*0.015+(50166222*(1+0.09)^1)*-0.051+(50166222*(1+0.09)^1)*-0.009)/(1+0.08)^3.5) + (((50166222*(1+0.09)^2)*0.076*(1-0.19)+(50166222*(1+0.09)^2)*0.015+(50166222*(1+0.09)^2)*-0.051+(50166222*(1+0.09)^2)*-0.009)/(1+0.08)^4.5) + (((50166222*(1+0.09)^3)*0.076*(1-0.19)+(50166222*(1+0.09)^3)*0.015+(50166222*(1+0.09)^3)*-0.051+(50166222*(1+0.09)^3)*-0.009)/(1+0.08)^5.5) + (((50166222*(1+0.09)^4)*0.076*(1-0.19)+(50166222*(1+0.09)^4)*0.015+(50166222*(1+0.09)^4)*-0.051+(50166222*(1+0.09)^4)*-0.009)/(1+0.08)^6.5)+((50166222*(1+0.09)^4)*0.076*(1-0.19)+(50166222*(1+0.09)^4)*0.015+(50166222*(1+0.09)^4)*-0.051+(50166222*(1+0.09)^4)*-0.009)*(1+0.03)/(0.08-0.03)/(1+0.08)^7-32464-17720)/98040*1000 -> 180410.35 | H23: =('DCF Valuation'!D20/(1+0.08)^0.5 + 'DCF Valuation'!E20/(1+0.08)^1.5 + 'DCF Valuation'!F20/(1+0.08)^2.5+(((50166222*(1+0.1)^1)*0.076*(1-0.19)+(50166222*(1+0.1)^1)*0.015+(50166222*(1+0.1)^1)*-0.051+(50166222*(1+0.1)^1)*-0.009)/(1+0.08)^3.5) + (((50166222*(1+0.1)^2)*0.076*(1-0.19)+(50166222*(1+0.1)^2)*0.015+(50166222*(1+0.1)^2)*-0.051+(50166222*(1+0.1)^2)*-0.009)/(1+0.08)^4.5) + (((50166222*(1+0.1)^3)*0.076*(1-0.19)+(50166222*(1+0.1)^3)*0.015+(50166222*(1+0.1)^3)*-0.051+(50166222*(1+0.1)^3)*-0.009)/(1+0.08)^5.5) + (((50166222*(1+0.1)^4)*0.076*(1-0.19)+(50166222*(1+0.1)^4)*0.015+(50166222*(1+0.1)^4)*-0.051+(50166222*(1+0.1)^4)*-0.009)/(1+0.08)^6.5)+((50166222*(1+0.1)^4)*0.076*(1-0.19)+(50166222*(1+0.1)^4)*0.015+(50166222*(1+0.1)^4)*-0.051+(50166222*(1+0.1)^4)*-0.009)*(1+0.03)/(0.08-0.03)/(1+0.08)^7-32464-17720)/98040*1000 -> 186424.9
B24: 0.08 | D24: =('DCF Valuation'!D20/(1+0.08)^0.5 + 'DCF Valuation'!E20/(1+0.08)^1.5 + 'DCF Valuation'!F20/(1+0.08)^2.5+(((50166222*(1+0.06)^1)*0.08*(1-0.19)+(50166222*(1+0.06)^1)*0.015+(50166222*(1+0.06)^1)*-0.051+(50166222*(1+0.06)^1)*-0.009)/(1+0.08)^3.5) + (((50166222*(1+0.06)^2)*0.08*(1-0.19)+(50166222*(1+0.06)^2)*0.015+(50166222*(1+0.06)^2)*-0.051+(50166222*(1+0.06)^2)*-0.009)/(1+0.08)^4.5) + (((50166222*(1+0.06)^3)*0.08*(1-0.19)+(50166222*(1+0.06)^3)*0.015+(50166222*(1+0.06)^3)*-0.051+(50166222*(1+0.06)^3)*-0.009)/(1+0.08)^5.5) + (((50166222*(1+0.06)^4)*0.08*(1-0.19)+(50166222*(1+0.06)^4)*0.015+(50166222*(1+0.06)^4)*-0.051+(50166222*(1+0.06)^4)*-0.009)/(1+0.08)^6.5)+((50166222*(1+0.06)^4)*0.08*(1-0.19)+(50166222*(1+0.06)^4)*0.015+(50166222*(1+0.06)^4)*-0.051+(50166222*(1+0.06)^4)*-0.009)*(1+0.03)/(0.08-0.03)/(1+0.08)^7-32464-17720)/98040*1000 -> 193679.96 | E24: =('DCF Valuation'!D20/(1+0.08)^0.5 + 'DCF Valuation'!E20/(1+0.08)^1.5 + 'DCF Valuation'!F20/(1+0.08)^2.5+(((50166222*(1+0.07)^1)*0.08*(1-0.19)+(50166222*(1+0.07)^1)*0.015+(50166222*(1+0.07)^1)*-0.051+(50166222*(1+0.07)^1)*-0.009)/(1+0.08)^3.5) + (((50166222*(1+0.07)^2)*0.08*(1-0.19)+(50166222*(1+0.07)^2)*0.015+(50166222*(1+0.07)^2)*-0.051+(50166222*(1+0.07)^2)*-0.009)/(1+0.08)^4.5) + (((50166222*(1+0.07)^3)*0.08*(1-0.19)+(50166222*(1+0.07)^3)*0.015+(50166222*(1+0.07)^3)*-0.051+(50166222*(1+0.07)^3)*-0.009)/(1+0.08)^5.5) + (((50166222*(1+0.07)^4)*0.08*(1-0.19)+(50166222*(1+0.07)^4)*0.015+(50166222*(1+0.07)^4)*-0.051+(50166222*(1+0.07)^4)*-0.009)/(1+0.08)^6.5)+((50166222*(1+0.07)^4)*0.08*(1-0.19)+(50166222*(1+0.07)^4)*0.015+(50166222*(1+0.07)^4)*-0.051+(50166222*(1+0.07)^4)*-0.009)*(1+0.03)/(0.08-0.03)/(1+0.08)^7-32464-17720)/98040*1000 -> 200316.87 | F24: =('DCF Valuation'!D20/(1+0.08)^0.5 + 'DCF Valuation'!E20/(1+0.08)^1.5 + 'DCF Valuation'!F20/(1+0.08)^2.5+(((50166222*(1+0.08)^1)*0.08*(1-0.19)+(50166222*(1+0.08)^1)*0.015+(50166222*(1+0.08)^1)*-0.051+(50166222*(1+0.08)^1)*-0.009)/(1+0.08)^3.5) + (((50166222*(1+0.08)^2)*0.08*(1-0.19)+(50166222*(1+0.08)^2)*0.015+(50166222*(1+0.08)^2)*-0.051+(50166222*(1+0.08)^2)*-0.009)/(1+0.08)^4.5) + (((50166222*(1+0.08)^3)*0.08*(1-0.19)+(50166222*(1+0.08)^3)*0.015+(50166222*(1+0.08)^3)*-0.051+(50166222*(1+0.08)^3)*-0.009)/(1+0.08)^5.5) + (((50166222*(1+0.08)^4)*0.08*(1-0.19)+(50166222*(1+0.08)^4)*0.015+(50166222*(1+0.08)^4)*-0.051+(50166222*(1+0.08)^4)*-0.009)/(1+0.08)^6.5)+((50166222*(1+0.08)^4)*0.08*(1-0.19)+(50166222*(1+0.08)^4)*0.015+(50166222*(1+0.08)^4)*-0.051+(50166222*(1+0.08)^4)*-0.009)*(1+0.03)/(0.08-0.03)/(1+0.08)^7-32464-17720)/98040*1000 -> 207135.23 | G24: =('DCF Valuation'!D20/(1+0.08)^0.5 + 'DCF Valuation'!E20/(1+0.08)^1.5 + 'DCF Valuation'!F20/(1+0.08)^2.5+(((50166222*(1+0.09)^1)*0.08*(1-0.19)+(50166222*(1+0.09)^1)*0.015+(50166222*(1+0.09)^1)*-0.051+(50166222*(1+0.09)^1)*-0.009)/(1+0.08)^3.5) + (((50166222*(1+0.09)^2)*0.08*(1-0.19)+(50166222*(1+0.09)^2)*0.015+(50166222*(1+0.09)^2)*-0.051+(50166222*(1+0.09)^2)*-0.009)/(1+0.08)^4.5) + (((50166222*(1+0.09)^3)*0.08*(1-0.19)+(50166222*(1+0.09)^3)*0.015+(50166222*(1+0.09)^3)*-0.051+(50166222*(1+0.09)^3)*-0.009)/(1+0.08)^5.5) + (((50166222*(1+0.09)^4)*0.08*(1-0.19)+(50166222*(1+0.09)^4)*0.015+(50166222*(1+0.09)^4)*-0.051+(50166222*(1+0.09)^4)*-0.009)/(1+0.08)^6.5)+((50166222*(1+0.09)^4)*0.08*(1-0.19)+(50166222*(1+0.09)^4)*0.015+(50166222*(1+0.09)^4)*-0.051+(50166222*(1+0.09)^4)*-0.009)*(1+0.03)/(0.08-0.03)/(1+0.08)^7-32464-17720)/98040*1000 -> 214138.38 | H24: =('DCF Valuation'!D20/(1+0.08)^0.5 + 'DCF Valuation'!E20/(1+0.08)^1.5 + 'DCF Valuation'!F20/(1+0.08)^2.5+(((50166222*(1+0.1)^1)*0.08*(1-0.19)+(50166222*(1+0.1)^1)*0.015+(50166222*(1+0.1)^1)*-0.051+(50166222*(1+0.1)^1)*-0.009)/(1+0.08)^3.5) + (((50166222*(1+0.1)^2)*0.08*(1-0.19)+(50166222*(1+0.1)^2)*0.015+(50166222*(1+0.1)^2)*-0.051+(50166222*(1+0.1)^2)*-0.009)/(1+0.08)^4.5) + (((50166222*(1+0.1)^3)*0.08*(1-0.19)+(50166222*(1+0.1)^3)*0.015+(50166222*(1+0.1)^3)*-0.051+(50166222*(1+0.1)^3)*-0.009)/(1+0.08)^5.5) + (((50166222*(1+0.1)^4)*0.08*(1-0.19)+(50166222*(1+0.1)^4)*0.015+(50166222*(1+0.1)^4)*-0.051+(50166222*(1+0.1)^4)*-0.009)/(1+0.08)^6.5)+((50166222*(1+0.1)^4)*0.08*(1-0.19)+(50166222*(1+0.1)^4)*0.015+(50166222*(1+0.1)^4)*-0.051+(50166222*(1+0.1)^4)*-0.009)*(1+0.03)/(0.08-0.03)/(1+0.08)^7-32464-17720)/98040*1000 -> 221329.68
B25: Base case highlighted (EBIT Margin=6.8%, Rev Growth=9.0%). WACC=8.0%, TGR=3.0% held constant.
B28: TABLE 3 — Implied Share Price vs. WACC × EBIT Margin
B29: WACC ↓ / EBIT Margin → | D29: 0.06 | E29: 0.064 | F29: 0.068 | G29: 0.072 | H29: 0.076 | I29: 0.08
B30: 0.07 | D30: =('DCF Valuation'!D20/(1+0.07)^0.5 + 'DCF Valuation'!E20/(1+0.07)^1.5 + 'DCF Valuation'!F20/(1+0.07)^2.5+(((50166222*(1+0.09)^1)*0.06*(1-0.19)+(50166222*(1+0.09)^1)*0.015+(50166222*(1+0.09)^1)*-0.051+(50166222*(1+0.09)^1)*-0.009)/(1+0.07)^3.5) + (((50166222*(1+0.09)^2)*0.06*(1-0.19)+(50166222*(1+0.09)^2)*0.015+(50166222*(1+0.09)^2)*-0.051+(50166222*(1+0.09)^2)*-0.009)/(1+0.07)^4.5) + (((50166222*(1+0.09)^3)*0.06*(1-0.19)+(50166222*(1+0.09)^3)*0.015+(50166222*(1+0.09)^3)*-0.051+(50166222*(1+0.09)^3)*-0.009)/(1+0.07)^5.5) + (((50166222*(1+0.09)^4)*0.06*(1-0.19)+(50166222*(1+0.09)^4)*0.015+(50166222*(1+0.09)^4)*-0.051+(50166222*(1+0.09)^4)*-0.009)/(1+0.07)^6.5)+((50166222*(1+0.09)^4)*0.06*(1-0.19)+(50166222*(1+0.09)^4)*0.015+(50166222*(1+0.09)^4)*-0.051+(50166222*(1+0.09)^4)*-0.009)*(1+0.03)/(0.07-0.03)/(1+0.07)^7-32464-17720)/98040*1000 -> 56434.61 | E30: =('DCF Valuation'!D20/(1+0.07)^0.5 + 'DCF Valuation'!E20/(1+0.07)^1.5 + 'DCF Valuation'!F20/(1+0.07)^2.5+(((50166222*(1+0.09)^1)*0.064*(1-0.19)+(50166222*(1+0.09)^1)*0.015+(50166222*(1+0.09)^1)*-0.051+(50166222*(1+0.09)^1)*-0.009)/(1+0.07)^3.5) + (((50166222*(1+0.09)^2)*0.064*(1-0.19)+(50166222*(1+0.09)^2)*0.015+(50166222*(1+0.09)^2)*-0.051+(50166222*(1+0.09)^2)*-0.009)/(1+0.07)^4.5) + (((50166222*(1+0.09)^3)*0.064*(1-0.19)+(50166222*(1+0.09)^3)*0.015+(50166222*(1+0.09)^3)*-0.051+(50166222*(1+0.09)^3)*-0.009)/(1+0.07)^5.5) + (((50166222*(1+0.09)^4)*0.064*(1-0.19)+(50166222*(1+0.09)^4)*0.015+(50166222*(1+0.09)^4)*-0.051+(50166222*(1+0.09)^4)*-0.009)/(1+0.07)^6.5)+((50166222*(1+0.09)^4)*0.064*(1-0.19)+(50166222*(1+0.09)^4)*0.015+(50166222*(1+0.09)^4)*-0.051+(50166222*(1+0.09)^4)*-0.009)*(1+0.03)/(0.07-0.03)/(1+0.07)^7-32464-17720)/98040*1000 -> 99828.286 | F30: =('DCF Valuation'!D20/(1+0.07)^0.5 + 'DCF Valuation'!E20/(1+0.07)^1.5 + 'DCF Valuation'!F20/(1+0.07)^2.5+(((50166222*(1+0.09)^1)*0.068*(1-0.19)+(50166222*(1+0.09)^1)*0.015+(50166222*(1+0.09)^1)*-0.051+(50166222*(1+0.09)^1)*-0.009)/(1+0.07)^3.5) + (((50166222*(1+0.09)^2)*0.068*(1-0.19)+(50166222*(1+0.09)^2)*0.015+(50166222*(1+0.09)^2)*-0.051+(50166222*(1+0.09)^2)*-0.009)/(1+0.07)^4.5) + (((50166222*(1+0.09)^3)*0.068*(1-0.19)+(50166222*(1+0.09)^3)*0.015+(50166222*(1+0.09)^3)*-0.051+(50166222*(1+0.09)^3)*-0.009)/(1+0.07)^5.5) + (((50166222*(1+0.09)^4)*0.068*(1-0.19)+(50166222*(1+0.09)^4)*0.015+(50166222*(1+0.09)^4)*-0.051+(50166222*(1+0.09)^4)*-0.009)/(1+0.07)^6.5)+((50166222*(1+0.09)^4)*0.068*(1-0.19)+(50166222*(1+0.09)^4)*0.015+(50166222*(1+0.09)^4)*-0.051+(50166222*(1+0.09)^4)*-0.009)*(1+0.03)/(0.07-0.03)/(1+0.07)^7-32464-17720)/98040*1000 -> 143221.96 | G30: =('DCF Valuation'!D20/(1+0.07)^0.5 + 'DCF Valuation'!E20/(1+0.07)^1.5 + 'DCF Valuation'!F20/(1+0.07)^2.5+(((50166222*(1+0.09)^1)*0.072*(1-0.19)+(50166222*(1+0.09)^1)*0.015+(50166222*(1+0.09)^1)*-0.051+(50166222*(1+0.09)^1)*-0.009)/(1+0.07)^3.5) + (((50166222*(1+0.09)^2)*0.072*(1-0.19)+(50166222*(1+0.09)^2)*0.015+(50166222*(1+0.09)^2)*-0.051+(50166222*(1+0.09)^2)*-0.009)/(1+0.07)^4.5) + (((50166222*(1+0.09)^3)*0.072*(1-0.19)+(50166222*(1+0.09)^3)*0.015+(50166222*(1+0.09)^3)*-0.051+(50166222*(1+0.09)^3)*-0.009)/(1+0.07)^5.5) + (((50166222*(1+0.09)^4)*0.072*(1-0.19)+(50166222*(1+0.09)^4)*0.015+(50166222*(1+0.09)^4)*-0.051+(50166222*(1+0.09)^4)*-0.009)/(1+0.07)^6.5)+((50166222*(1+0.09)^4)*0.072*(1-0.19)+(50166222*(1+0.09)^4)*0.015+(50166222*(1+0.09)^4)*-0.051+(50166222*(1+0.09)^4)*-0.009)*(1+0.03)/(0.07-0.03)/(1+0.07)^7-32464-17720)/98040*1000 -> 186615.64 | H30: =('DCF Valuation'!D20/(1+0.07)^0.5 + 'DCF Valuation'!E20/(1+0.07)^1.5 + 'DCF Valuation'!F20/(1+0.07)^2.5+(((50166222*(1+0.09)^1)*0.076*(1-0.19)+(50166222*(1+0.09)^1)*0.015+(50166222*(1+0.09)^1)*-0.051+(50166222*(1+0.09)^1)*-0.009)/(1+0.07)^3.5) + (((50166222*(1+0.09)^2)*0.076*(1-0.19)+(50166222*(1+0.09)^2)*0.015+(50166222*(1+0.09)^2)*-0.051+(50166222*(1+0.09)^2)*-0.009)/(1+0.07)^4.5) + (((50166222*(1+0.09)^3)*0.076*(1-0.19)+(50166222*(1+0.09)^3)*0.015+(50166222*(1+0.09)^3)*-0.051+(50166222*(1+0.09)^3)*-0.009)/(1+0.07)^5.5) + (((50166222*(1+0.09)^4)*0.076*(1-0.19)+(50166222*(1+0.09)^4)*0.015+(50166222*(1+0.09)^4)*-0.051+(50166222*(1+0.09)^4)*-0.009)/(1+0.07)^6.5)+((50166222*(1+0.09)^4)*0.076*(1-0.19)+(50166222*(1+0.09)^4)*0.015+(50166222*(1+0.09)^4)*-0.051+(50166222*(1+0.09)^4)*-0.009)*(1+0.03)/(0.07-0.03)/(1+0.07)^7-32464-17720)/98040*1000 -> 230009.32 | I30: =('DCF Valuation'!D20/(1+0.07)^0.5 + 'DCF Valuation'!E20/(1+0.07)^1.5 + 'DCF Valuation'!F20/(1+0.07)^2.5+(((50166222*(1+0.09)^1)*0.08*(1-0.19)+(50166222*(1+0.09)^1)*0.015+(50166222*(1+0.09)^1)*-0.051+(50166222*(1+0.09)^1)*-0.009)/(1+0.07)^3.5) + (((50166222*(1+0.09)^2)*0.08*(1-0.19)+(50166222*(1+0.09)^2)*0.015+(50166222*(1+0.09)^2)*-0.051+(50166222*(1+0.09)^2)*-0.009)/(1+0.07)^4.5) + (((50166222*(1+0.09)^3)*0.08*(1-0.19)+(50166222*(1+0.09)^3)*0.015+(50166222*(1+0.09)^3)*-0.051+(50166222*(1+0.09)^3)*-0.009)/(1+0.07)^5.5) + (((50166222*(1+0.09)^4)*0.08*(1-0.19)+(50166222*(1+0.09)^4)*0.015+(50166222*(1+0.09)^4)*-0.051+(50166222*(1+0.09)^4)*-0.009)/(1+0.07)^6.5)+((50166222*(1+0.09)^4)*0.08*(1-0.19)+(50166222*(1+0.09)^4)*0.015+(50166222*(1+0.09)^4)*-0.051+(50166222*(1+0.09)^4)*-0.009)*(1+0.03)/(0.07-0.03)/(1+0.07)^7-32464-17720)/98040*1000 -> 273402.99
B31: 0.075 | D31: =('DCF Valuation'!D20/(1+0.075)^0.5 + 'DCF Valuation'!E20/(1+0.075)^1.5 + 'DCF Valuation'!F20/(1+0.075)^2.5+(((50166222*(1+0.09)^1)*0.06*(1-0.19)+(50166222*(1+0.09)^1)*0.015+(50166222*(1+0.09)^1)*-0.051+(50166222*(1+0.09)^1)*-0.009)/(1+0.075)^3.5) + (((50166222*(1+0.09)^2)*0.06*(1-0.19)+(50166222*(1+0.09)^2)*0.015+(50166222*(1+0.09)^2)*-0.051+(50166222*(1+0.09)^2)*-0.009)/(1+0.075)^4.5) + (((50166222*(1+0.09)^3)*0.06*(1-0.19)+(50166222*(1+0.09)^3)*0.015+(50166222*(1+0.09)^3)*-0.051+(50166222*(1+0.09)^3)*-0.009)/(1+0.075)^5.5) + (((50166222*(1+0.09)^4)*0.06*(1-0.19)+(50166222*(1+0.09)^4)*0.015+(50166222*(1+0.09)^4)*-0.051+(50166222*(1+0.09)^4)*-0.009)/(1+0.075)^6.5)+((50166222*(1+0.09)^4)*0.06*(1-0.19)+(50166222*(1+0.09)^4)*0.015+(50166222*(1+0.09)^4)*-0.051+(50166222*(1+0.09)^4)*-0.009)*(1+0.03)/(0.075-0.03)/(1+0.075)^7-32464-17720)/98040*1000 -> 50361.642 | E31: =('DCF Valuation'!D20/(1+0.075)^0.5 + 'DCF Valuation'!E20/(1+0.075)^1.5 + 'DCF Valuation'!F20/(1+0.075)^2.5+(((50166222*(1+0.09)^1)*0.064*(1-0.19)+(50166222*(1+0.09)^1)*0.015+(50166222*(1+0.09)^1)*-0.051+(50166222*(1+0.09)^1)*-0.009)/(1+0.075)^3.5) + (((50166222*(1+0.09)^2)*0.064*(1-0.19)+(50166222*(1+0.09)^2)*0.015+(50166222*(1+0.09)^2)*-0.051+(50166222*(1+0.09)^2)*-0.009)/(1+0.075)^4.5) + (((50166222*(1+0.09)^3)*0.064*(1-0.19)+(50166222*(1+0.09)^3)*0.015+(50166222*(1+0.09)^3)*-0.051+(50166222*(1+0.09)^3)*-0.009)/(1+0.075)^5.5) + (((50166222*(1+0.09)^4)*0.064*(1-0.19)+(50166222*(1+0.09)^4)*0.015+(50166222*(1+0.09)^4)*-0.051+(50166222*(1+0.09)^4)*-0.009)/(1+0.075)^6.5)+((50166222*(1+0.09)^4)*0.064*(1-0.19)+(50166222*(1+0.09)^4)*0.015+(50166222*(1+0.09)^4)*-0.051+(50166222*(1+0.09)^4)*-0.009)*(1+0.03)/(0.075-0.03)/(1+0.075)^7-32464-17720)/98040*1000 -> 88378.864 | F31: =('DCF Valuation'!D20/(1+0.075)^0.5 + 'DCF Valuation'!E20/(1+0.075)^1.5 + 'DCF Valuation'!F20/(1+0.075)^2.5+(((50166222*(1+0.09)^1)*0.068*(1-0.19)+(50166222*(1+0.09)^1)*0.015+(50166222*(1+0.09)^1)*-0.051+(50166222*(1+0.09)^1)*-0.009)/(1+0.075)^3.5) + (((50166222*(1+0.09)^2)*0.068*(1-0.19)+(50166222*(1+0.09)^2)*0.015+(50166222*(1+0.09)^2)*-0.051+(50166222*(1+0.09)^2)*-0.009)/(1+0.075)^4.5) + (((50166222*(1+0.09)^3)*0.068*(1-0.19)+(50166222*(1+0.09)^3)*0.015+(50166222*(1+0.09)^3)*-0.051+(50166222*(1+0.09)^3)*-0.009)/(1+0.075)^5.5) + (((50166222*(1+0.09)^4)*0.068*(1-0.19)+(50166222*(1+0.09)^4)*0.015+(50166222*(1+0.09)^4)*-0.051+(50166222*(1+0.09)^4)*-0.009)/(1+0.075)^6.5)+((50166222*(1+0.09)^4)*0.068*(1-0.19)+(50166222*(1+0.09)^4)*0.015+(50166222*(1+0.09)^4)*-0.051+(50166222*(1+0.09)^4)*-0.009)*(1+0.03)/(0.075-0.03)/(1+0.075)^7-32464-17720)/98040*1000 -> 126396.09 | G31: =('DCF Valuation'!D20/(1+0.075)^0.5 + 'DCF Valuation'!E20/(1+0.075)^1.5 + 'DCF Valuation'!F20/(1+0.075)^2.5+(((50166222*(1+0.09)^1)*0.072*(1-0.19)+(50166222*(1+0.09)^1)*0.015+(50166222*(1+0.09)^1)*-0.051+(50166222*(1+0.09)^1)*-0.009)/(1+0.075)^3.5) + (((50166222*(1+0.09)^2)*0.072*(1-0.19)+(50166222*(1+0.09)^2)*0.015+(50166222*(1+0.09)^2)*-0.051+(50166222*(1+0.09)^2)*-0.009)/(1+0.075)^4.5) + (((50166222*(1+0.09)^3)*0.072*(1-0.19)+(50166222*(1+0.09)^3)*0.015+(50166222*(1+0.09)^3)*-0.051+(50166222*(1+0.09)^3)*-0.009)/(1+0.075)^5.5) + (((50166222*(1+0.09)^4)*0.072*(1-0.19)+(50166222*(1+0.09)^4)*0.015+(50166222*(1+0.09)^4)*-0.051+(50166222*(1+0.09)^4)*-0.009)/(1+0.075)^6.5)+((50166222*(1+0.09)^4)*0.072*(1-0.19)+(50166222*(1+0.09)^4)*0.015+(50166222*(1+0.09)^4)*-0.051+(50166222*(1+0.09)^4)*-0.009)*(1+0.03)/(0.075-0.03)/(1+0.075)^7-32464-17720)/98040*1000 -> 164413.31 | H31: =('DCF Valuation'!D20/(1+0.075)^0.5 + 'DCF Valuation'!E20/(1+0.075)^1.5 + 'DCF Valuation'!F20/(1+0.075)^2.5+(((50166222*(1+0.09)^1)*0.076*(1-0.19)+(50166222*(1+0.09)^1)*0.015+(50166222*(1+0.09)^1)*-0.051+(50166222*(1+0.09)^1)*-0.009)/(1+0.075)^3.5) + (((50166222*(1+0.09)^2)*0.076*(1-0.19)+(50166222*(1+0.09)^2)*0.015+(50166222*(1+0.09)^2)*-0.051+(50166222*(1+0.09)^2)*-0.009)/(1+0.075)^4.5) + (((50166222*(1+0.09)^3)*0.076*(1-0.19)+(50166222*(1+0.09)^3)*0.015+(50166222*(1+0.09)^3)*-0.051+(50166222*(1+0.09)^3)*-0.009)/(1+0.075)^5.5) + (((50166222*(1+0.09)^4)*0.076*(1-0.19)+(50166222*(1+0.09)^4)*0.015+(50166222*(1+0.09)^4)*-0.051+(50166222*(1+0.09)^4)*-0.009)/(1+0.075)^6.5)+((50166222*(1+0.09)^4)*0.076*(1-0.19)+(50166222*(1+0.09)^4)*0.015+(50166222*(1+0.09)^4)*-0.051+(50166222*(1+0.09)^4)*-0.009)*(1+0.03)/(0.075-0.03)/(1+0.075)^7-32464-17720)/98040*1000 -> 202430.53 | I31: =('DCF Valuation'!D20/(1+0.075)^0.5 + 'DCF Valuation'!E20/(1+0.075)^1.5 + 'DCF Valuation'!F20/(1+0.075)^2.5+(((50166222*(1+0.09)^1)*0.08*(1-0.19)+(50166222*(1+0.09)^1)*0.015+(50166222*(1+0.09)^1)*-0.051+(50166222*(1+0.09)^1)*-0.009)/(1+0.075)^3.5) + (((50166222*(1+0.09)^2)*0.08*(1-0.19)+(50166222*(1+0.09)^2)*0.015+(50166222*(1+0.09)^2)*-0.051+(50166222*(1+0.09)^2)*-0.009)/(1+0.075)^4.5) + (((50166222*(1+0.09)^3)*0.08*(1-0.19)+(50166222*(1+0.09)^3)*0.015+(50166222*(1+0.09)^3)*-0.051+(50166222*(1+0.09)^3)*-0.009)/(1+0.075)^5.5) + (((50166222*(1+0.09)^4)*0.08*(1-0.19)+(50166222*(1+0.09)^4)*0.015+(50166222*(1+0.09)^4)*-0.051+(50166222*(1+0.09)^4)*-0.009)/(1+0.075)^6.5)+((50166222*(1+0.09)^4)*0.08*(1-0.19)+(50166222*(1+0.09)^4)*0.015+(50166222*(1+0.09)^4)*-0.051+(50166222*(1+0.09)^4)*-0.009)*(1+0.03)/(0.075-0.03)/(1+0.075)^7-32464-17720)/98040*1000 -> 240447.75
